Workbook

Sheet Summary
C2: Project | E2: Spreadsmart
C3: Project Manager | E3: ManishkumarNanjibhai Buhecha
C4: Test Team Members | E4: Neha Bharti, Aswini, Anit, Archana
C7: Test Case Summary
C8: Test Case Count | D8: =SUM(D10:D14)
C9: Total Executed Test Cases | E9: Executed Tests | F9: Total Tests
C10: Passed | D10: =SUM(E18:E45) | E10: =IF(D10=0,,(D10/(D10+D11))) | F10: =IF(D9=0,,(D10/D9))
C11: Failed | D11: =SUM(F18:F45) | E11: =IF(D11=0,,(D11/(D10+D11))) | F11: =IF(D9=0,,(D11/D9))
C12: Blocked | D12: =SUM(G18:G45) | E12: 0 | F12: 0
C13: Pending | D13: =SUM(H18:H45) | E13: 0 | F13: 0
C14: Not Applicable | D14: =SUM(I18:I45) | E14: 0 | F14: 0
C16: Feature-wise Test Case Result
C17: Feature Name | D17: Total test cases | E17: PASS | F17: FAIL | G17: Blocked | H17: Pending | I17: NA
C18: SSO Login | D18: ='SSO Login'!D3 | E18: ='SSO Login'!D4 | F18: ='SSO Login'!D5 | G18: ='SSO Login'!D6 | H18: ='SSO Login'!D7 | I18: ='SSO Login'!D8
C19: Login Screen | D19: =SUM('Login Screen'!D3) | E19: =SUM('Login Screen'!D4) | F19: =SUM('Login Screen'!D5) | G19: =SUM('Login Screen'!D6) | H19: =SUM('Login Screen'!D7) | I19: =SUM('Login Screen'!D8)
C20: Security Test | D20: ='Security Test'!D4 | E20: ='Security Test'!D5 | F20: ='Security Test'!D6 | G20: ='Security Test'!D7 | H20: ='Security Test'!D8 | I20: ='Security Test'!D9
C21: Dashboard | D21: =SUM(Dashboard!D3) | E21: =SUM(Dashboard!D4) | F21: =SUM(Dashboard!D5) | G21: =SUM(Dashboard!D6) | H21: =SUM(Dashboard!D7) | I21: =SUM(Dashboard!D8)
C22: Customer Screen | D22: =SUM('Customer Screen'!D3) | E22: =SUM('Customer Screen'!D4) | F22: =SUM('Customer Screen'!D5) | G22: =SUM('Customer Screen'!D6) | H22: =SUM('Customer Screen'!D7) | I22: =SUM('Customer Screen'!D8)
C23: Item Creation | D23: =SUM('Item Creation'!D3) | E23: =SUM('Item Creation'!D4) | F23: =SUM('Item Creation'!D5) | G23: =SUM('Item Creation'!D6) | H23: =SUM('Item Creation'!D7) | I23: =SUM('Item Creation'!D8)
C24: Spreading Screen_Pdf | D24: =SUM('Spreading Screen_Pdf File'!C3) | E24: =SUM('Spreading Screen_Pdf File'!C4) | F24: =SUM('Spreading Screen_Pdf File'!C5) | G24: =SUM('Spreading Screen_Pdf File'!C6) | H24: =SUM('Spreading Screen_Pdf File'!C7) | I24: =SUM('Spreading Screen_Pdf File'!C8)
C25: Spreading Screen_Excel file | D25: =SUM('Spreading Screen_Excel File'!D3) | E25: =SUM('Spreading Screen_Excel File'!D4) | F25: =SUM('Spreading Screen_Excel File'!D5) | G25: =SUM('Spreading Screen_Excel File'!D6) | H25: =SUM('Spreading Screen_Excel File'!D7) | I25: =SUM('Spreading Screen_Excel File'!D8)
C26: Expressions | D26: ='Expressions Verification'!D3 | E26: ='Expressions Verification'!D4 | F26: ='Expressions Verification'!D5 | G26: ='Expressions Verification'!D6 | H26: ='Expressions Verification'!D7 | I26: ='Expressions Verification'!D8
C27: Statement Export | D27: ='Statement Export'!D3 | E27: ='Statement Export'!D4 | F27: ='Statement Export'!D5 | G27: ='Statement Export'!D6 | H27: ='Statement Export'!D7 | I27: ='Statement Export'!D8
C28: Model Management | D28: =SUM('Model Management'!D3) | E28: =SUM('Model Management'!D4) | F28: =SUM('Model Management'!D5) | G28: =SUM('Model Management'!D6) | H28: =SUM('Model Management'!D7) | I28: =SUM('Model Management'!D8)
C29: Clean Pdf | D29: ='Clean PDF'!D3 | E29: ='Clean PDF'!D4 | F29: ='Clean PDF'!D5 | G29: ='Clean PDF'!D6 | H29: ='Clean PDF'!D7 | I29: ='Clean PDF'!D8
C30: Split Pdf | D30: ='Split Pdf'!D3 | E30: ='Split Pdf'!D4 | F30: ='Split Pdf'!D5 | G30: ='Split Pdf'!D6 | H30: ='Split Pdf'!D7 | I30: ='Split Pdf'!D8
C31: Reporting | D31: =SUM(Reporting!D3) | E31: =SUM(Reporting!D4) | F31: =SUM(Reporting!D5) | G31: =SUM(Reporting!D6) | H31: =SUM(Reporting!D7) | I31: =SUM(Reporting!D8)
C32: Admin Screen | D32: =SUM('Admin Screen'!D3) | E32: =SUM('Admin Screen'!D4) | F32: =SUM('Admin Screen'!D5) | G32: =SUM('Admin Screen'!D6) | H32: =SUM('Admin Screen'!D7) | I32: =SUM('Admin Screen'!D8)
C33: Customer Zone | D33: =SUM('Customer Zone'!D3) | E33: =SUM('Customer Zone'!D4) | F33: =SUM('Customer Zone'!D5) | G33: =SUM('Customer Zone'!D6) | H33: =SUM('Customer Zone'!D7) | I33: =SUM('Customer Zone'!D8)
C34: Currency Conversion | D34: ='Currency Conversion'!D3 | E34: ='Currency Conversion'!D4 | F34: ='Currency Conversion'!D5 | G34: ='Currency Conversion'!D6 | H34: ='Currency Conversion'!D7 | I34: ='Currency Conversion'!D8
C35: AIML Training | D35: =SUM('AIML Training'!D3) | E35: =SUM('AIML Training'!D4) | F35: =SUM('AIML Training'!D5) | G35: =SUM('AIML Training'!D6) | H35: =SUM('AIML Training'!D7) | I35: =SUM('AIML Training'!D8)
C36: Notes Processing | D36: =SUM('Notes Processing'!D3) | E36: =SUM('Notes Processing'!D4) | F36: =SUM('Notes Processing'!D5) | G36: =SUM('Notes Processing'!D6) | H36: =SUM('Notes Processing'!D7) | I36: =SUM('Notes Processing'!D8)
C37: Maker Checker | D37: =SUM('Maker Checker'!D3) | E37: =SUM('Maker Checker'!D4) | F37: =SUM('Maker Checker'!D5) | G37: =SUM('Maker Checker'!D6) | H37: =SUM('Maker Checker'!D7) | I37: =SUM('Maker Checker'!D8)
C38: Taxonomy | D38: =SUM(Taxonomy!D3) | E38: =SUM(Taxonomy!D4) | F38: =SUM(Taxonomy!D5) | G38: =SUM(Taxonomy!D6) | H38: =SUM(Taxonomy!D7) | I38: =SUM(Taxonomy!D8)
C39: Exclusion | D39: =SUM(Exclusion!D3) | E39: =SUM(Exclusion!D4) | F39: =SUM(Exclusion!D5) | G39: =SUM(Exclusion!D6) | H39: =SUM(Exclusion!D7) | I39: =SUM(Exclusion!D8)
C40: Autofill Matrix | D40: ='Autofill Matrix'!D3 | E40: ='Autofill Matrix'!D4 | F40: ='Autofill Matrix'!D5 | G40: ='Autofill Matrix'!D6 | H40: ='Autofill Matrix'!D7 | I40: ='Autofill Matrix'!D8
C41: Document Classification | D41: ='Document Classification'!D4 | E41: ='Document Classification'!D5 | F41: ='Document Classification'!D6 | G41: ='Document Classification'!D7 | H41: ='Document Classification'!D8 | I41: ='Document Classification'!D9
C42: Notes Processing-L2 | D42: ='Notes Processing-L2'!D4 | E42: ='Notes Processing-L2'!D5 | F42: ='Notes Processing-L2'!D6 | G42: ='Notes Processing-L2'!D7 | H42: ='Notes Processing-L2'!D8 | I42: ='Notes Processing-L2'!D9
C43: NAICS | D43: =NAICS!D4 | E43: =NAICS!D5 | F43: =NAICS!D6 | G43: =NAICS!D7 | H43: =NAICS!D8 | I43: =NAICS!D9
C44: Covenant | D44: =#REF! | E44: =#REF! | F44: =#REF! | G44: =#REF! | H44: =#REF! | I44: =#REF!
...

Sheet SSO Login
B2: Test Case Summary
B3: Total Test Cases | D3: =SUM(D4:D8) | E3: Executed Tests | F3: Total Tests | G3: Automation Scripts
B4: Passed | D4: =COUNTIF(F9:F34,"Passed") | E4: =IF(D4=0,,(D4/(D4+D5))) | F4: =IF(D3=0,,(D4/D3)) | G4: =COUNTIF(H10:H493,"Done")
B5: Failed | D5: =COUNTIF(F9:F139,"Failed") | E5: =IF(D5=0,,(D5/(D5+D6))) | F5: =IF(D3=0,,(D5/D3)) | G5: =COUNTIF(H10:H493,"Failed")
B6: Blocked | D6: =COUNTIF(F9:F139,"Blocked") | E6: =IF(D6=0,,(D6/(D6+D7))) | F6: =IF(D3=0,,(D6/D3)) | G6: =COUNTIF(H10:H493,"Blocked")
B7: Pending | D7: =COUNTIF(F9:F139,"Pending") | E7: =IF(D7=0,,(D7/(D7+D8))) | F7: =IF(D3=0,,(D7/D3)) | G7: =COUNTIF(H10:H493,"Pending")
B8: Not Applicable | D8: =COUNTIF(F10:F139,"NA") | E8: =IF(D8=0,,(D8/(D8+D9))) | F8: =IF(D3=0,,(D8/D3)) | G8: =COUNTIF(H10:H493,"Out of Scope")
B9: S.No. | C9: Module/Sub-Module | D9: Test Steps | E9: Expected Results | F9: Result | G9: Bug ID | H9: Automation Status | I9: Mapped Scripts | J9: Comments
B10: SSOLogin_001 | C10: Login Page | D10: Open the Spreadsmart URL as a registered user and verify that the sign-in page is displayed with Email and Password fields. | E10: The sign-in page should be displayed, and the user should be able to proceed with valid credentials. | F10: NA | H10: Out of Scope
B11: SSOLogin_002 | C11: Login - New User | D11: Click the "Login with SSO" button on the login page. | E11: The button should be clickable. | F11: NA | H11: Out of Scope
B12: SSOLogin_003 | C12: Login - Existing User | D12: Sign in with valid credentials for an existing user. | E12: The user should be able to navigate to the page available for the assigned role. | F12: NA | H12: Out of Scope
B13: SSOLogin_004 | C13: Login - Invalid User | D13: Attempt to sign in with invalid user credentials and observe the validation message. | E13: A validation message should be displayed indicating that the username or password is invalid. | F13: NA | H13: Out of Scope
B14: SSOLogin_005 | C14: Login - Rejected User | D14: Attempt to sign in with a rejected user account and verify the validation message. | E14: The user should not be able to sign in and should receive the message "Your account has not been approved." | F14: NA | H14: Out of Scope
B15: SSOLogin_006 | C15: Login - Inactive User | D15: Attempt to sign in with an inactive user account and verify the validation message. | E15: The user should not be able to sign in and should receive the message "Your account has not been approved." | F15: NA | H15: Out of Scope
B16: SSOLogin_007 | C16: Login - Incorrect Password | D16: Attempt to sign in with an incorrect password and observe the response. | E16: A validation message should be displayed during sign-in. | F16: NA | H16: Out of Scope
B17: SSOLogin_008 | C17: Login - Invalid Domain | D17: Attempt to register with an unsupported email domain. | E17: A message should be displayed indicating that email IDs from this domain are not supported. | F17: NA | G17: Message is different | H17: Out of Scope
B18: SSOLogin_009 | C18: Login - Cross Browser | D18: Verify the login flow in different browsers (Chrome and Microsoft Edge). | E18: Login should work in all supported browsers. | F18: NA | H18: Out of Scope
B19: SSOLogin_010 | C19: Login - Close Tab | D19: Close the Spreadsmart window, then reopen the login URL. | E19: The user should be able to navigate to the page available for the assigned role. | F19: NA | H19: Out of Scope
B20: SSOLogin_011 | C20: Duplicate Tab | D20: Duplicate an already opened application tab and observe the new tab. | E20: The Spreadsmart application should open in the duplicated tab with the same user session. | F20: NA | H20: Out of Scope
B21: SSOLogin_012 | C21: Copy URL | D21: Sign in to the application, copy the URL, and paste it into a second tab. | E21: The sign-in page should be displayed to the user. | F21: NA | H21: Out of Scope
B22: SSOLogin_013 | C22: Login - Admin | D22: Sign in with a user who has the Admin role and verify the landing screen. | E22: The user should be able to sign in and view all options available to the Admin role. | F22: NA | H22: Out of Scope
B23: SSOLogin_014 | C23: Login - Analyst | D23: Sign in with a user who has the Analyst role and verify the landing screen. | E23: The user should be able to sign in and view all options available to the Analyst role. | F23: NA | H23: Out of Scope
B24: SSOLogin_015 | C24: Login - Global Manager | D24: Sign in with a user who has the Global Manager role and verify the landing screen. | E24: The user should be able to sign in and view all options available to the Global Manager role. | F24: NA | H24: Out of Scope
B25: SSOLogin_016 | C25: Login - Manager | D25: Sign in with a user who has the Manager role and verify the landing screen. | E25: The user should be able to sign in and view all options available to the Manager role. | F25: NA | H25: Out of Scope
B26: SSOLogin_017 | C26: Logout Button | D26: After signing in to Spreadsmart, click the Logout button. | E26: The user should be logged out and redirected to the sign-in page. | F26: NA | H26: Out of Scope
B27: SSOLogin_018 | C27: Logout Page | D27: After logout, verify that the user must enter credentials again to sign in. | E27: The sign-in page should be displayed, and the user should be prompted to enter credentials again. | F27: NA | H27: Out of Scope
B28: SSOLogin_019 | C28: Logout - Admin | D28: Sign in with an Admin user, then click the Logout button and observe the behavior. | E28: The Admin user should be able to log out successfully. | F28: NA | H28: Out of Scope
B29: SSOLogin_020 | C29: Logout - Analyst | D29: Sign in with an Analyst user, then click the Logout button and observe the behavior. | E29: The Analyst user should be able to log out successfully. | F29: NA | H29: Out of Scope
... B35: SSOLogin_026 | C35: Logout - Cross Browser | D35: Verify the logout flow in different browsers (Chrome and Microsoft Edge). | E35: Logout and sign-in should work in all supported browsers. | F35: NA | H35: Out of Scope
B36: SSOLogin_027 | C36: Login Page | D36: Verify the behavior when the screen becomes blank during SSO login. | E36: Login should complete successfully. | F36: NA | G36: 136306 | H36: Out of Scope | J36: [Needs QA Review: original wording ambiguous]

Sheet Login Screen
B2: Test Case Summary
B3: Total Test Cases | D3: =SUM(D4:D8) | E3: Executed Tests | F3: Total Tests | G3: Automation Scripts
B4: Passed | D4: =COUNTIF(F10:F98,"Passed") | E4: =IF(D4=0,,(D4/(D4+D5))) | F4: =IF(D3=0,,(D4/D3)) | G4: =COUNTIF(H10:H493,"Done")
B5: Failed | D5: =COUNTIF(F10:F98,"Failed") | E5: =IF(D5=0,,(D5/(D5+D6))) | F5: =IF(D3=0,,(D5/D3)) | G5: =COUNTIF(H10:H493,"Failed")
B6: Blocked | D6: =COUNTIF(F10:F98,"Blocked") | E6: =IF(D6=0,,(D6/(D6+D7))) | F6: =IF(D3=0,,(D6/D3)) | G6: =COUNTIF(H10:H493,"Blocked")
B7: Pending | D7: =COUNTIF(F10:F98,"Pending") | E7: =IF(D7=0,,(D7/(D7+D8))) | F7: =IF(D3=0,,(D7/D3)) | G7: =COUNTIF(H10:H493,"Pending")
B8: Not Applicable | D8: =COUNTIF(F10:F98,"NA") | E8: =IF(D8=0,,(D8/(D8+D9))) | F8: =IF(D3=0,,(D8/D3)) | G8: =COUNTIF(H10:H493,"Out of Scope")
B9: S.No. | C9: Module/Sub-Module | D9: Test Steps | E9: Expected Results | F9: Result | G9: Bug ID | H9: Automation Status | I9: Mapped Scripts | J9: Comments
B10: Login_001 | C10: Register Screen | D10: Click the "Register here" link on the login page. | E10: The Register Now page should open, and the cursor should be placed in the First Name field. | F10: Passed | H10: Pending | J10: 0.25
B11: Login_002 | C11: Register Screen | D11: Enter alphabetic, numeric, and alphanumeric values in the First Name and Last Name fields. | E11: The entered values should be displayed in the fields. | F11: Passed | H11: Pending | J11: 0.25
B12: Login_003 | C12: Register Screen | D12: Enter an email ID in the required format. | E12: A valid email ID format should be accepted. | F12: Passed | H12: Pending | J12: 0.25
B13: Login_004 | C13: Register Screen | D13: Enter a Windows user ID in the User ID field. | E13: The user should be able to enter the User ID. | F13: Passed | H13: Pending | J13: 0.25
B14: Login_005 | C14: Register Screen | D14: Enter a password with at least 8 characters, including one special character, one uppercase letter, one lowercase letter, and one number. Then enter the same value in the Confirm Password field. | E14: The password should meet the validation rules, and the values entered in the Password and Confirm Password fields should be masked. | F14: Passed | H14: Pending | J14: 0.5
B15: Login_006 | C15: Register Screen | D15: Click the "Register Now" button. | E15: A "User Registered Successfully" pop-up should be displayed. | F15: Passed | H15: Pending | J15: 0.25
B16: Login_007 | C16: Login Screen | D16: After the user is approved, click the "Windows Login" button to proceed. | E16: Windows login should work for an approved user. | F16: Passed | H16: Out of Scope
B17: Login_008 | C17: Login Screen | D17: 1. Attempt login with the correct user ID and an incorrect password. 2. Attempt login with the correct password and an incorrect user ID. | E17: An "Incorrect password or username" message should be displayed. | F17: Passed | H17: Pending | J17: 0.5
B18: Login_009 | C18: Login Screen | D18: Attempt login with an email ID from an invalid domain. | E18: The system should not accept the unsupported domain. | F18: Passed | H18: Pending | J18: 0.5
B19: Login_010 | C19: Forgot Password | D19: Click "Forgot Password", enter an email ID, verify that the email is received, open the reset link, enter a new password, and log in with the new password. | E19: A reset email should be received, the reset link should work, and the user should be able to log in with the new password. | F19: Passed | H19: Out of Scope | J19: As of now we're not covering Email verification in automation
B20: Login_011 | C20: Forgot Password | D20: Enter an incorrect email ID in the Forgot Password flow. Then verify the behavior when the old password is used in the Reset Password window. | E20: No reset email should be received, and the user should be prompted to set a new password. | F20: Passed | H20: Out of Scope | J20: As of now we're not covering Email verification in automation
B21: Login_012 | C21: Login Screen | D21: Click the Windows Login button and proceed to the Spreadsmart application. | E21: The Dashboard should open. | F21: Passed | H21: Done
B22: Login_013 | C22: Login Screen | D22: Verify the Terms of Use and Privacy Policy links on the login page. | E22: The links should be visible and clickable. | F22: Passed | H22: Pending | J22: 0.5
B23: Login_014 | C23: Login Screen | D23: Attempt to log in with a user who has not yet been approved. | E23: An appropriate validation message should be displayed. | F23: Passed | G23: 136312 | H23: Pending

Sheet Security Test
B2: Test Case Summary
B3: Total Test Cases | D3: 1st Iteration | E3: Executed Tests | F3: Total Tests | G3: Automation Scripts
D4: =SUM(D5:D9)
B5: Passed | D5: =COUNTIF(F11:F273,"Passed") | E5: =IF(D5=0,,(D5/(D5+D6))) | F5: =IF(D4=0,,(D5/D4)) | G5: =COUNTIF(H11:H494,"Done")
B6: Failed | D6: =COUNTIF(F11:F273,"Failed") | E6: =IF(D6=0,,(D6/(D6+D7))) | F6: =IF(D4=0,,(D6/D4)) | G6: =COUNTIF(H11:H494,"Failed")
B7: Blocked | D7: =COUNTIF(F11:F273,"Blocked") | E7: =IF(D7=0,,(D7/(D7+D8))) | F7: =IF(D4=0,,(D7/D4)) | G7: =COUNTIF(H11:H494,"Blocked")
B8: Pending | D8: =COUNTIF(F11:F273,"Pending") | E8: =IF(D8=0,,(D8/(D8+D9))) | F8: =IF(D4=0,,(D8/D4)) | G8: =COUNTIF(H11:H494,"Pending")
B9: Not Applicable | D9: =COUNTIF(F11:F273,"Not Applicable") | E9: =IF(D9=0,,(D9/(D9+#REF!))) | F9: =IF(D4=0,,(D9/D4)) | G9: =COUNTIF(H11:H494,"Out of Scope")
B10: S.No. | C10: Module/Sub-Module | D10: Test Steps | E10: Expected Results | F10: Result | G10: Bug ID | H10: Automation Status | I10: Mapped Scripts | J10: Comments
B11: Security_001 | C11: Login Screen | D11: Enter alphabetic, numeric, and alphanumeric values in the First Name and Last Name fields. | E11: The entered values should be displayed in the fields. | F11: Pending | H11: Pending | J11: 0.25
B12: Security_002 | C12: Login Screen | D12: Enter an email ID in the required format. | E12: A valid email ID format should be accepted. | F12: Pending | H12: Pending | J12: 0.25
B13: Security_003 | C13: Login Screen | D13: Enter a Windows user ID in the User ID field. | E13: The user should be able to enter the User ID. | F13: Pending | H13: Pending | J13: 0.25
B14: Security_004 | C14: Login Screen | D14: Enter a password with at least 8 characters, including one special character, one uppercase letter, one lowercase letter, and one number. Then enter the same value in the Confirm Password field. | E14: The password should meet the validation rules, and the values entered in the Password and Confirm Password fields should be masked. | F14: Pending | H14: Pending | J14: 0.25
B15: Security_005 | C15: Login Screen | D15: 1. Attempt login with the correct user ID and an incorrect password. 2. Attempt login with the correct password and an incorrect user ID. | E15: An "Incorrect password or username" message should be displayed. | F15: Pending | H15: Pending | J15: 0.5
B16: Security_006 | C16: Login Screen | D16: Attempt login with an email ID from an invalid domain. | E16: The system should not accept the unsupported domain. | F16: Pending | H16: Pending | J16: 0.5
B17: Security_007 | C17: Login Screen | D17: Enter an incorrect email ID in the Forgot Password flow. Then verify the behavior when the old password is used in the Reset Password window. | E17: No reset email should be received, and the user should be prompted to set a new password. | F17: Pending | H17: Out of Scope
B18: Security_008 | C18: Login Screen | D18: Attempt to copy and paste data into the email and password fields. | E18: The user should not be allowed to paste data into these fields. | F18: Pending | H18: Pending | J18: 0.5
B19: Security_009 | C19: Login Screen | D19: Attempt to log in with an unapproved account. | E19: The user should receive a message stating that the account has not been approved. | F19: Pending | H19: Pending | J19: 1
B20: Security_010 | C20: Group Access | D20: Provide a user with access to limited groups and log in with that user. Then view data in Existing Customers, Models, and Reports. | E20: The user should see data only for the assigned groups. Data for other groups should not be visible. | F20: Pending | H20: Pending | J20: 1
B21: Security_011 | C21: Group Access | D21: Provide a user with access to limited groups and log in with that user. Then go to Statement Export and review the customer and model lists. | E21: Only customers and models linked to the accessible groups should be displayed. | F21: Pending | H21: Pending | J21: 1
B22: Security_012 | C22: Admin | D22: Verify that an Admin user can access the features defined for the role in the role matrix. | E22: The Admin user should have access according to the configured role matrix. | F22: Pending | G22: 70778 | H22: Pending | I22: 2 | J22: ..\Downloads\Roles and Rights Sample.docx
B23: Security_013 | C23: Manager | D23: Verify that a Manager user can access the features defined for the role in the role matrix. | E23: The Manager user should have access according to the configured role matrix. | F23: Pending | H23: Pending | J23: 2
B24: Security_014 | C24: Global Manager | D24: Verify that a Global Manager user can access the features defined for the role in the role matrix. | E24: The Global Manager user should have access according to the configured role matrix. | F24: Pending | H24: Pending | J24: 2
B25: Security_015 | C25: Analyst | D25: Verify that an Analyst user can access the features defined for the role in the role matrix. | E25: The Analyst user should have access according to the configured role matrix. | F25: Pending | H25: Pending | J25: 2
B26: Security_016 | C26: Login Screen | D26: Attempt to log in with an inactive user account. | E26: The user should not be able to log in and should receive the message "Your account has not been approved." | F26: Pending | G26: Newly added | H26: Pending | J26: 1
B27: Security_017 | C27: Login Screen | D27: Attempt to log in with a rejected user account. | E27: The user should not be able to log in and should receive the message "Your account has not been approved." | F27: Pending | G27: Newly added | H27: Pending | J27: 1
B28: Security_018 | C28: Login Screen | D28: Log in to Spreadsmart. While the session is active, have another user reject or deactivate the account. | E28: The current user should be able to continue working until the session expires. | F28: Pending | G28: Newly added | H28: Out of Scope | J28: multiple session in parallel is not supported in cypress
B29: Security_019 | C29: Access Issue | D29: Log in to Spreadsmart. While the session is active, have another user change the access from Admin to Manager or another role. | E29: The current user should be able to continue working until the session expires. | F29: Pending | G29: Newly added | H29: Out of Scope

Sheet Dashboard
B2: Test Case Summary
B3: Total Test Cases | D3: =SUM(D4:D8) | E3: Executed Tests | F3: Total Tests | G3: Automation Scripts
B4: Passed | D4: =COUNTIF(F9:F46,"Passed") | E4: =IF(D4=0,,(D4/(D4+D5))) | F4: =IF(D3=0,,(D4/D3)) | G4: =COUNTIF(H10:H489,"Done")
B5: Failed | D5: =COUNTIF(F9:F46,"Failed") | E5: =IF(D5=0,,(D5/(D5+D6))) | F5: =IF(D3=0,,(D5/D3)) | G5: =COUNTIF(H10:H489,"Failed")
B6: Blocked | D6: =COUNTIF(F9:F46,"Blocked") | E6: =IF(D6=0,,(D6/(D6+D7))) | F6: =IF(D3=0,,(D6/D3)) | G6: =COUNTIF(H10:H489,"Blocked")
B7: Pending | D7: =COUNTIF(F9:F46,"Pending") | E7: =IF(D7=0,,(D7/(D7+D8))) | F7: =IF(D3=0,,(D7/D3)) | G7: =COUNTIF(H10:H489,"Pending")
B8: Not Applicable | D8: =COUNTIF(F9:F46,"Not Applicable") | E8: =IF(D8=0,,(D8/(D8+#REF!))) | F8: =IF(D3=0,,(D8/D3)) | G8: =COUNTIF(H10:H489,"Out of Scope")
B9: S.No. | C9: Module/Sub-Module | D9: Test Steps | E9: Expected Results | F9: Result | G9: Bug ID | H9: Automation Status | I9: Mapped Scripts | J9: Comments
B10: Dash_001 | C10: Dashboard | D10: Log in to Spreadsmart using Analyst or Admin credentials. | E10: The user should be able to log in to the application. | F10: Pending | H10: Done
B11: Dash_002 | C11: Dashboard | D11: Observe the first screen after login. | E11: The Dashboard should be displayed after login. | F11: Pending | H11: Done
B12: Dash_003 | C12: Dashboard | D12: Verify that the Dashboard menu is present on the home screen. | E12: The home screen should display Dashboard, Spreading, Reporting, and Admin sections. | F12: Pending | H12: Done
B13: Dash_004 | C13: Dashboard | D13: Verify that the Dashboard displays the following options: Spreads Overall Projects Project Assignment Status | E13: The listed options should be displayed. | F13: Pending | H13: Done
B14: Dash_005 | C14: Dashboard | D14: Verify that Overall Projects displays a graph for item statuses such as Received, Draft, For QC, Spread, Hold, Rejected, and All. | E14: The graph should be displayed. | F14: Pending | H14: Done
B15: Dash_006 | C15: Dashboard | D15: Verify that the Spreads section displays status tabs such as Received, Draft, For QC, Spread, Hold, Rejected, and All. Then review the customer details shown under each status. | E15: Customer details such as Customer Name, Group, For Spread, and Analyst Name should be displayed. | F15: Pending | H15: Done
B16: Dash_007 | C16: Statement Date Filter | D16: Apply the Statement Date filter and observe the data. | E16: Data should be displayed according to the selected statement date. | F16: Pending | H16: Done
B17: Dash_008 | C17: Group Filter | D17: 1. Apply the Group filter and select a group. Observe the results in the Received, Draft, Hold, Spread, For QC, Rejected, and All tabs. 2. Select a group with no data and review all tabs. | E17: 1. Data should appear according to the selected group. 2. No data should appear in any tab for a group with no data. | F17: Pending | H17: Done
B18: Dash_009 | C18: Graph | D18: Verify the graph after applying different filters: 1. Group filter 2. Statement Date filter | E18: The graph should display data according to the applied filters. | F18: Pending | H18: Done
B19: Dash_010 | C19: Graph | D19: Apply a Statement Date filter for which no data is available. | E19: The graph should display the message "No data available." | F19: Pending | H19: Done
B20: Dash_011 | C20: Group Filter | D20: Log in with a group that has no data available and observe the Dashboard. | E20: The Dashboard should show "No data available" and should not display data for other groups. | F20: Pending | H20: Done
B21: Dash_012 | C21: Dashboard | D21: Verify that Project Assignment Status shows the number of spreads and the average time taken. | E21: The Project Assignment Status graph should be displayed. | F21: Pending | H21: Done
... B25: Dash_016 | C25: Pagination | D25: Precondition: A large number of items should be available. Scroll down the page, click the next page, and then change the number of items from the dropdown. | E25: The user should be navigated to the selected page, and the selected item count should be applied from the dropdown. | F25: Pending | H25: Done
B26: Dash_018 | C26: Tab Switching | D26: Log in to the dashboard URL, then switch to another tab and return to the application tab. Verify the behavior when the reported error occurs after login and after tab switching. | E26: The Dashboard should remain accessible when switching tabs. | F26: Pending | G26: 136550 | H26: Pending | J26: [Needs QA Review: original expected result missing]

Sheet Customer Screen
B2: Test Case Summary
B3: Total Test Cases | D3: =SUM(D4:D8) | E3: Executed Tests | F3: Total Tests | G3: Automation Scripts
B4: Passed | D4: =COUNTIF(F10:F101,"Passed") | E4: =IF(D4=0,,(D4/(D4+D5))) | F4: =IF(D3=0,,(D4/D3)) | G4: =COUNTIF(H10:H494,"Done")
B5: Failed | D5: =COUNTIF(F10:F101,"Failed") | E5: =IF(D5=0,,(D5/(D5+D6))) | F5: =IF(D3=0,,(D5/D3)) | G5: =COUNTIF(H10:H494,"Failed")
B6: Blocked | D6: =COUNTIF(F10:F101,"Blocked") | E6: =IF(D6=0,,(D6/(D6+D7))) | F6: =IF(D3=0,,(D6/D3)) | G6: =COUNTIF(H10:H494,"Blocked")
B7: Pending | D7: =COUNTIF(F10:F101,"Pending") | E7: =IF(D7=0,,(D7/(D7+D8))) | F7: =IF(D3=0,,(D7/D3)) | G7: =COUNTIF(H10:H494,"Pending")
B8: Not Applicable | D8: =COUNTIF(F10:F101,"Not Applicable") | E8: =IF(D8=0,,(D8/(D8+#REF!))) | F8: =IF(D3=0,,(D8/D3)) | G8: =COUNTIF(H10:H494,"Out of Scope")
B9: S.No. | C9: Module/Sub-Module | D9: Test Steps | E9: Expected Results | F9: Result | G9: Bug ID | H9: Automation Status | I9: Mapped Scripts | J9: Comments
B10: Cust_001 | C10: Create Customer | D10: Log in to Spreadsmart, navigate to Create Customer, and review the available options. | E10: The Create Customer page should open. | F10: Pending | H10: Done | I10: automationTestScenario.js
B11: Cust_002 | C11: Create Customer | D11: Verify that the Create Customer screen displays the following fields: Customer Name Customer ID Year End Group Ticker QC Date Range Target Currency Size of Business Comments Submit button | E11: The listed fields should be displayed on the screen. | F11: Pending | H11: Done
B12: Cust_003 | C12: Create Customer | D12: Enter values in the mandatory and optional fields, save the customer, then navigate to the Existing Customer screen and review the created record. | E12: The user should be able to create the customer and view it in the customer list. | F12: Pending | H12: Done | I12: automationTestScenario.js
B13: Cust_004 | C13: Create Customer | D13: Enter a duplicate Customer ID and submit. Then enter a duplicate customer name and submit. | E13: A duplicate Customer ID should not be allowed. A duplicate customer name should be allowed. | F13: Pending | H13: Done
B14: Cust_005 | C14: Existing Customer | D14: Log in to Spreadsmart and navigate to the Existing Customer page from the Spreading menu. | E14: The Existing Customer page should be displayed. | F14: Pending | H14: Done | I14: automationTestScenario.js
B15: Cust_006 | C15: Existing Customer | D15: Open the Existing Customer page and review the displayed columns. | E15: The Existing Customer page should display columns such as Customer Name, Entity Type, Group Name, For Spread, Status, and Actions. | F15: Pending | H15: Done
B16: Cust_007 | C16: Existing Customer | D16: Open the Existing Customer page and click a Customer Name to load the customer information page. Verify that the page shows Customer Name, Customer ID, Year End, Group, Ticker, QC, Date Range, NAICS Suggestions, Target Currency, Size of Business, Comments, and Submit. | E16: All listed fields should be displayed as editable. | F16: Pending | H16: Done
B17: Cust_008 | C17: Customer Information | D17: Ensure all mandatory (*) fields contain valid values, then click Update. | E17: The customer should be updated successfully, and a "Customer successfully updated" message should be displayed. | F17: Pending | H17: Done
B18: Cust_009 | C18: My Favourite | D18: Click the star icon to add a customer to favourites. Then open My Favourite, select the customer, and click Modify. | E18: The user should be navigated to the Modify Customer page, and the page should display the data entered during customer creation. | F18: Pending | H18: Done
B19: Cust_010 | C19: Validate 'Favorite' Functionality | D19: Open the customer listing page and click the favourite (star) icon for a customer. | E19: The star icon should be filled, and the customer should appear under My Favourite. | F19: Pending | H19: Done
B20: Cust_011 | C20: Check Customers Under 'My Favourite' | D20: Verify the My Favourite page when no customer is marked as favourite. | E20: No customer should be displayed on the customer list page. | F20: Pending | H20: Done
B21: Cust_012 | C21: Check Customers Under 'My Favourite' | D21: 1. Mark customers as favourite. 2. Review the My Favourite page. | E21: All customers marked as favourite by the logged-in user should be displayed under My Favourite. | F21: Pending | H21: Done
B22: Cust_013 | C22: Validate 'UnFavorite' Functionality | D22: Open the customer listing page, click the favourite (star) icon for a customer, and then click it again. | E22: The star icon should be cleared, and the customer should be removed from My Favourite. | F22: Pending | H22: Done
B23: Cust_014 | C23: Check Customers Under 'My Favourite' | D23: 1. Mark customers as unfavourite. 2. Review the My Favourite page. | E23: Customers marked as unfavourite by the logged-in user should be removed from My Favourite. | F23: Pending | H23: Done
B24: Cust_015 | C24: Customer Listing | D24: Open My Favourite and click a customer name on the customer listing page. | E24: The page should display the data entered during customer creation. | F24: Pending | H24: Done
B25: Cust_016 | C25: Modify Customer | D25: Click a customer name on the customer listing page, modify the customer metadata, and update the information. | E25: The user should be able to modify the customer data. | F25: Pending | H25: Done
B26: Cust_017 | C26: Modify Customer | D26: Navigate to Existing Customer, open any customer record, select the QC checkbox and date range, then click Update. | E26: The Start Date and End Date should be displayed after the customer is updated. | F26: Pending | H26: Done
... B31: Cust_022 | C31: NAICS | D31: On the Modify Customer screen, review the NAICS suggestion. After selecting a NAICS value, leave mandatory fields blank in the details table and click Update. | E31: Validation errors should be displayed for the mandatory fields, and the update should not be completed. | F31: Pending | H31: Done
B32: Cust_023 | C32: NAICS | D32: Verify the delete functionality for NAICS after adding multiple NAICS entries with different percentages. | E32: NAICS data should be deleted successfully. The total percentage for added NAICS entries should remain 100%. | F32: Pending | H32: Pending | I32: 0.5
B33: Cust_024 | C33: Modify Customer | D33: Modify any customer from Existing Customers, clear mandatory fields, and click Update. | E33: The system should display validation messages for the missing mandatory fields. | F33: Pending | G33: Newly Added | H33: Pending | I33: 0.5 | J33: 44922
B34: Cust_025 | C34: Modify Customer - Additional Information | D34: Review the Additional Information section for Add User and Add Customer Details. | E34: The user should be able to add user and customer details in this section. | F34: Pending | H34: Pending | I34: 0.5
B35: Cust_026 | C35: Modify Customer - Additional Information | D35: Review the Add Customer Details section and verify the mandatory fields. | E35: The user should be able to enter all required fields under Customer Details. | F35: Pending | H35: Pending | I35: 0.25
B36: Cust_027 | C36: Modify Customer - Additional Information | D36: Validate the mandatory-field messages for the Add Customer Details fields. | E36: Error messages should be displayed for missing mandatory fields in Add Customer Details. | F36: Pending | H36: Pending | I36: 0.25
B37: Cust_028 | C37: Modify Customer | D37: Precondition: The customer should have submitted items. Modify the customer, edit the Group field, review the group list in the dropdown, and select or unselect groups as applicable. | E37: All selected groups should be visible in the Group dropdown. The user should be able to uncheck only groups for which items are not submitted. Groups with submitted items should remain disabled for editing. | F37: Pending | G37: Newly Added | H37: Pending | I37: 1 | J37: 44922
B38: Cust_029 | C38: Update Comments | D38: Add comments for a customer, then edit the comments multiple times and update each time. | E38: The user should be able to edit and update comments each time without issues. | F38: Pending | G38: Newly Added | H38: Pending | I38: 1 | J38: 44922
B39: Cust_030 | C39: Group | D39: Precondition: A group containing "&" should exist in the system, for example Cash & Taxes. Create a customer with the specified group, then modify the customer and select multiple such groups. Review the Customer Listing screen. | E39: The group should be selected correctly and should be reflected consistently across all screens. | F39: Pending | G39: Newly Added | H39: Pending | I39: 1 | J39: 44922
B40: Cust_031 | C40: Create/Modify Customer | D40: Validate the QC and Date Range functionality during customer creation or modification. | E40: After selecting the QC checkbox, the user should be able to add the date range for QC. | F40: Pending | H40: Pending | I40: 1

Sheet Item Creation
B2: Test Case Summary
B3: Total Test Cases | D3: =SUM(D4:D8) | E3: Executed Tests | F3: Total Tests | G3: Automation Scripts
B4: Passed | D4: =COUNTIF(F9:F42,"Passed") | E4: =IF(D4=0,,(D4/(D4+D5))) | F4: =IF(D3=0,,(D4/D3)) | G4: =COUNTIF(H10:H493,"Done")
B5: Failed | D5: =COUNTIF(F9:F110,"Failed") | E5: =IF(D5=0,,(D5/(D5+D6))) | F5: =IF(D3=0,,(D5/D3)) | G5: =COUNTIF(H10:H493,"Failed")
B6: Blocked | D6: =COUNTIF(F9:F110,"Blocked") | E6: =IF(D6=0,,(D6/(D6+D7))) | F6: =IF(D3=0,,(D6/D3)) | G6: =COUNTIF(H10:H493,"Blocked")
B7: Pending | D7: =COUNTIF(F9:F500,"Pending") | E7: =IF(D7=0,,(D7/(D7+D8))) | F7: =IF(D3=0,,(D7/D3)) | G7: =COUNTIF(H10:H493,"Pending")
B8: Not Applicable | D8: =COUNTIF(F9:F110,"Not Applicable") | E8: =IF(D8=0,,(D8/(D8+#REF!))) | F8: =IF(D3=0,,(D8/D3)) | G8: =COUNTIF(H10:H493,"Out of Scope")
B9: S.No. | C9: Module/Sub-Module | D9: Test Steps | E9: Expected Results | F9: Result | G9: Bug ID | H9: Automation Status | I9: Mapped Scripts | J9: Comments
B10: Item_001 | C10: Add Item | D10: Navigate to Spreading > Existing Customer > Action > Add Item. | E10: The Add Item option should be available. | F10: Pending | H10: Done
B11: Item_002 | C11: Add Item - Upload File from System | D11: 1. Open the Add New Item page. 2. Choose the option to browse and add an additional file. | E11: A "Choose File Type To Upload" pop-up with the File Upload field should be displayed. | F11: Pending | H11: Done
B12: Item_003 | C12: Add Item - Upload File from System | D12: 1. Select the file type as PDF, Word, JPEG, or PNG. 2. Click Choose in the File Upload section. 3. Select the file. 4. Click Open. Note: Word files are converted to PDF automatically for spreading. | E12: 1. The selected file category should be applied. 2. Only supported files for the selected category should be shown. 3. The user should be able to change the drive. 4. The file should be uploaded, and a "Successfully uploaded" pop-up should be displayed. | F12: Pending | H12: Done
B13: Item_004 | C13: Add 100 MB File | D13: Select a 100 MB file from the system, upload it, and save the item. | E13: The user should be able to upload the file and save the item. | F13: Pending | H13: Blocked | I13: https://github.com/abramenal/cypress-file-upload/issues/273 | J13: Issue with uploading large size file
B14: Item_005 | C14: Add Different File Formats | D14: Upload the following file formats: Doc, DOCX, RTF Excel (XLSX, XLSM, XLTX) Image (PNG, JPEG) | E14: The system should support all the listed formats. | F14: Pending | H14: Done
B15: Item_006 | C15: Split File - PDF | D15: Add an item and select a PDF file. After upload, review the Split Yes/No option in the ribbon, save the item, and observe the Spread button. | E15: The file should be processed and saved. The Spread button should remain disabled until processing is complete. | F15: Pending | H15: Done
B16: Item_007 | C16: Split File - Excel | D16: Add an item and select an Excel file. Verify that Split is set to No by default for Excel, save the item, and click Spread. | E16: Split should be disabled for Excel, and the Spreading screen should open. | F16: Pending | H16: Done
B17: Item_008 | C17: Split File - PDF | D17: Upload a file, choose Split = No, and add the item. Then modify the item, change Split to Yes, update it, and observe the Spread button. | E17: The user should be able to change Split between Yes and No, and the Spread button should be enabled. | F17: Pending | H17: Done
B18: Item_009 | C18: Document Classification | D18: Upload a file and wait until processing starts. Verify that Document Classification begins and shows percentage progress until completion. | E18: Document Classification should start and display progress. | F18: Pending | H18: Done
B19: Item_010 | C19: Document Classification | D19: Verify that metadata is auto-populated after Document Classification is completed. | E19: Metadata should be auto-populated. | F19: Pending | H19: Done
B20: Item_011 | C20: Document Classification | D20: Verify that the auto-populated metadata matches the uploaded file. Also verify that manually entered values are not overwritten by predictions. | E20: The auto-populated metadata should be correct, and existing manually entered values should not be overwritten. | F20: Pending | H20: Done
B21: Item_012 | C21: Document Classification | D21: Upload an Excel file and observe the Document Classification process. | E21: Document Classification should be disabled for Excel files. | F21: Pending | H21: Done
B22: Item_013 | C22: Notes Processing | D22: Verify that Notes Processing starts and shows percentage progress once the file is processed. | E22: Notes Processing should start. | F22: Pending | H22: Done
B23: Item_014 | C23: Notes Processing | D23: Verify that Notes Processing starts even when AI/ML is set to No. | E23: Notes Processing should start. | F23: Pending | H23: Done
B24: Item_015 | C24: Notes Processing | D24: Verify that Notes Processing is disabled when an Excel file is uploaded. | E24: Notes Processing should be disabled for Excel files. | F24: Pending | H24: Done
B25: Item_016 | C25: Add Item - Upload File from System | D25: After uploading a file, select the language. Then review the prompt for Automatic Table Identification and choose Yes or No. | E25: After the option is selected, a status bar showing Upload, Processed, and Extracted should be displayed. | F25: Pending | H25: Done
... B42: Item_033 | C42: Action Button - Spread | D42: Verify that the user can open the Spreading screen using the Spread option under the Action button. | E42: The Spreading screen should be displayed. | F42: Pending | H42: Done
B43: Item_034 | C43: Action Button - Hold/Unhold | D43: Verify that the user can place an item on hold and remove the hold when an update is required. | E43: The item should move correctly between Hold and Unhold status, and the Hold icon should be displayed when applicable. | F43: Pending | H43: Pending | I43: 0.5
B44: Item_035 | C44: Action Button - Comments | D44: Verify that the Comments icon is enabled when comments are entered for an item. | E44: The added comments and related details should be displayed under the Comments icon. | F44: Pending | H44: Pending | I44: 0.25
B45: Item_036 | C45: Upload Large Files | D45: Upload files of 150 MB, 200 MB, 700 MB, and 1 GB while adding an item. | E45: The user should be allowed to upload files up to 1 GB. | F45: Pending | H45: Blocked | I45: https://github.com/abramenal/cypress-file-upload/issues/273 | J45: Issue with uploading large size file
B46: Item_037 | C46: Item Metadata | D46: Precondition: Group 1 should have multiple mapped models. Group 2 should have one mapped model that is also mapped to Group 1. Add an item from File Store, select Group 2 and review the model and Taxonomy Group. Then select Group 1, choose the same model, and review the Taxonomy Group again. | E46: The Taxonomy Group should always be auto-populated. | F46: Pending | H46: Done
B47: Item_038 | C47: Item Modify | D47: Add an item by uploading a file from the system, save it, then open Actions > Modify, add a new file, and save again. | E47: The item should be modified successfully, and the new file should be added. | F47: Pending | G47: Newly Added | H47: Done
B48: Item_039 | C48: Accountant Name | D48: Add or modify an item and review the Accountant Name field in the metadata section. | E48: The Accountant Name should be displayed in uppercase. | F48: Pending | G48: Newly Added | H48: Pending | I48: 0.25
B49: Item_040 | C49: YTD - Period | D49: On the Add Item screen, select the frequency and then check YTD. | E49: YTD should not change the Period value until a Statement Date is selected. | F49: Pending | G49: Newly Added | H49: Pending | I49: 1
B50: Item_041 | C50: YTD - Period | D50: On the Add Item screen, select the frequency and Statement Date. Then verify YTD behavior for different date ranges: 1. 1 Jan to 14 Jan 2. 15 Jan to 13 Feb 3. 14 Feb to 15 Mar 4. 16 Mar to 14 Apr 5. 15 Apr to 14 May etc. | E50: 1. For dates before 15 Jan, Period should be 0. 2. For 15 Jan to 13 Feb, YTD should be 1. 3. For 14 Feb to 15 Mar, YTD should be 2. 4. For 16 Mar to 14 Apr, YTD should be 3. 5. For 15 Apr to 14 May, YTD should be 4. 6. Subsequent date ranges should continue updating the Period accordingly. | F50: Pending | G50: Newly Added | H50: Pending | I50: 1
B51: Item_042 | C51: YTD Check/Uncheck | D51: On the Add Item screen, select the frequency and Statement Date, check YTD, review the Period, then uncheck YTD and review the Period again. | E51: Checking YTD should set the Period according to the selected Statement Date. Unchecking YTD should revert the change. | F51: Pending | G51: Newly Added | H51: Pending | I51: 1
B52: Item_043 | C52: Split All | D52: Open the Add Item screen, upload a file from the system, select Split = Yes or No, and click the preview after splitting. | E52: The file should not start processing until a Split selection is made. After Split = Yes is selected, processing should begin and the split file should be visible in the preview. | F52: Pending | G52: Newly Added | H52: Done
B53: Item_044 | C53: Split All | D53: On the Add Item screen, upload a file, select Split = No so that processing starts, then change the selection to Yes and review the behavior. | E53: When Split = No is selected, processing should start. If the selection is changed to Yes afterward, a pop-up should indicate that the file will be reprocessed, and processing should restart from 0%. | F53: Pending | G53: Newly Added | H53: Done
B54: Item_045 | C54: Split - Modify Screen | D54: Open any Modify Item screen, upload a file, and review the Split option. | E54: Split should be set to No by default. | F54: Pending | G54: Newly Added | H54: Done
B55: Item_046 | C55: View Item - Filters | D55: Validate the search results using different filters such as Statement Date Range, Status, Frequency, and Audit Method. | E55: Search results should be displayed according to the selected criteria. | F55: Pending | H55: Pending | I55: 0.5
B56: Item_047 | C56: View Item - Reset | D56: Click Reset/Refresh after applying filters. | E56: All search criteria should be reset to the default values. | F56: Pending | H56: Pending | I56: 0.5
B57: Item_048 | C57: View Item - Sent to QC and Direct QC Submit | D57: Validate the functionality for sending an added item to QC or directly submitting it to QC. | E57: The item should be available on the QC screen according to the Reporting Manager access configured for the user. | F57: Pending | H57: Pending | I57: 1
...

Sheet Spreading Screen_Pdf File
A2: Test Case Summary
A3: Total Test Cases | C3: =SUM(C4:C8) | D3: Executed Tests | E3: Total Tests | F3: Automation Scripts
A4: Passed | C4: =COUNTIF(E9:E249,"Passed") | D4: =IF(C4=0,,(C4/(C4+C5))) | E4: =IF(C3=0,,(C4/C3)) | F4: =COUNTIF(G10:G487,"Done")
A5: Failed | C5: =COUNTIF(E9:E249,"Failed") | D5: =IF(C5=0,,(C5/(C5+C6))) | E5: =IF(C3=0,,(C5/C3)) | F5: =COUNTIF(G10:G487,"Failed")
A6: Blocked | C6: =COUNTIF(E9:E249,"Blocked") | D6: =IF(C6=0,,(C6/(C6+C7))) | E6: =IF(C3=0,,(C6/C3)) | F6: =COUNTIF(G10:G487,"Blocked")
A7: Pending | C7: =COUNTIF(E9:E500,"Pending") | D7: =IF(C7=0,,(C7/(C7+C8))) | E7: =IF(C3=0,,(C7/C3)) | F7: =COUNTIF(G10:G487,"Pending")
A8: Not Applicable | C8: =COUNTIF(E9:E249,"Not Applicable") | D8: =IF(C8=0,,(C8/(C8+#REF!))) | E8: =IF(C3=0,,(C8/C3)) | F8: =COUNTIF(G10:G487,"Out of Scope")
A9: S.No. | B9: Module/Sub-Module | C9: Test Steps | D9: Expected Results | E9: Result | F9: Bug ID | G9: Automation Status | H9: Mapped Scripts | I9: Comments
A10: PDF_001 | B10: Spreading Screen - Landing Page | C10: Click Spread for a customer item on the Existing Items page. Verify that the screen opens on the page where the first zone is detected. If no table is detected, verify that the first page of the PDF opens. | D10: The user should be navigated to the page where the detected zone is tagged automatically. If no table is detected, the first page of the PDF should open. | E10: Pending | F10: Bug 78022 | G10: Done
A11: PDF_002 | B11: Spreading Screen - Zone Option Under Primary Category | C11: Open the Spreading screen and review the default primary category in the document pane. | D11: The Zone option should be displayed under the default primary category. | E11: Pending | G11: Pending | H11: 0.25
A12: PDF_003 | B12: Spreading Screen - Auto-detected Zones | C12: Open the Spreading screen, click Zone under the default primary category, and review the zones detected automatically by the system. | D12: All zones detected automatically by the system should be visible. | E12: Pending | G12: Done
A13: PDF_004 | B13: Spreading Screen - Zone Navigation | C13: Open the Spreading screen and select a zone from the default primary category. | D13: The user should be navigated to the page where the selected zone is tagged automatically. | E13: Pending | G13: Done
A14: PDF_005 | B14: Spreading Screen - Detect Table Option Under Primary Category | C14: Open the Spreading screen and review the default primary category in the document pane. | D14: The Detect Table option should be displayed under the default primary category. | E14: Pending | G14: Pending | H14: 0.25
A15: PDF_006 | B15: Spreading Screen - Detect Table Functionality | C15: 1. Open the Spreading screen. 2. Go to the page where a zone needs to be created in the financial document. 3. Click Detect Table under the primary category. | D15: A table should be created automatically with the detected columns, and Map Mode should be highlighted. | E15: Pending | G15: Done
A16: PDF_007 | B16: Spreading Screen - Tag Table | C16: Tag a detected table by selecting a zone name from the zone-tag dropdown. | D16: The table should be tagged with the selected zone name. | E16: Pending | G16: Done
A17: PDF_008 | B17: Spreading Screen - Line Item Column | C17: 1. Open the Spreading screen. 2. Detect a table on the required page. 3. Verify that the system identifies the line item column automatically. | D17: The selected line item column should be highlighted with a blue marker at the top. | E17: Pending | G17: Done
A18: PDF_009 | B18: Spreading Screen - Draw Table Option Under Primary Category | C18: Open the Spreading screen and review the default primary category in the document pane. | D18: The Draw Table option should be displayed under the default primary category. | E18: Pending | G18: Pending | H18: 0.25
A19: PDF_010 | B19: Spreading Screen - Draw Table Functionality | C19: 1. Go to the page where a zone needs to be created in the financial document. 2. Click Draw Table under the primary category. 3. Drag the cursor over the table area to create the table. | D19: The user should be able to create the table by dragging the cursor. | E19: Pending | G19: Out of Scope
A20: PDF_011 | B20: Spreading Screen - Line Item Column | C20: Verify that the system detects the line item column automatically. | D20: The selected line item column should be highlighted with a blue marker at the top. | E20: Pending | G20: Done
A21: PDF_012 | B21: Spreading Screen - Set Value Column | C21: Right-click the required column in a detected table and select Set Value Column. | D21: The selected column should be marked as the value column and highlighted with a green marker at the top. | E21: Pending | G21: Done
A22: PDF_013 | B22: Spreading Screen - Remove Value Column | C22: 1. Remove the value column when no values are mapped. 2. Remove the value column when values are already mapped. | D22: 1. The value column should be removed. 2. If mapped values exist, they should be converted to free text when the value column is removed. | E22: Pending | G22: Done
A23: PDF_014 | B23: Spreading Screen - Switch Value Column | C23: Switch the value column and verify the autofill behavior. | D23: The value column should be changed, and autofill should use the newly selected value column. | E23: Pending | G23: Done
A24: PDF_015 | B24: Spreading Screen - Visual Cue | C24: Select a value from the value column of a table and review the visual cue. | D24: The selected value should be displayed in the visual cue. | E24: Pending | G24: Done
A25: PDF_016 | B25: Spreading Screen - Optical Mapping | C25: Map a value from the financial statement to a model cell by single-clicking or double-clicking a value in the detected or drawn table and then mapping it to the model. | D25: The selected value should be mapped to the model. | E25: Pending | G25: Done
A26: PDF_017 | B26: Spreading Screen - Map Mode Toggle Visibility | C26: Open the Spreading screen and review the default primary category in the document pane. | D26: The Map Mode toggle should be displayed under the default primary category. | E26: Pending | G26: Pending | H26: 0.25
A27: PDF_018 | B27: Spreading Screen - Map/Edit Mode Toggle Action | C27: Open the Spreading screen and click the Map Mode toggle. | D27: After the toggle is clicked, the label should switch from Map Mode to Edit Mode. | E27: Pending | G27: Done
A28: PDF_019 | B28: Spreading Screen - Map Mode Functionality | C28: Open the Spreading screen, keep Map Mode active, map a few values from the current page to the model, and then click Mapped Values in the ribbon. | D28: All values mapped from the current page should be displayed in the Mapped Values pop-up. | E28: Pending | G28: Done
A29: PDF_020 | B29: Spreading Screen - Edit Mode Toggle Visibility | C29: Open the Spreading screen and click the Map Mode toggle. | D29: After the toggle is clicked, the button should switch to Edit Mode. | E29: Pending | G29: Done
A30: PDF_021 | B30: Spreading Screen - Edit Mode Functionality | C30: Open the Spreading screen, switch from Map Mode to Edit Mode, and review the table-editing behavior. | D30: The user should be able to edit table values in Edit Mode and continue mapping as supported. | E30: Pending | G30: Done
A31: PDF_022 | B31: Spreading Screen - Disable Single Click Toggle Visibility | C31: Open the Utilities dropdown on the Spreading screen. | D31: The Disable Single Click mapping option should be available and should be disabled by default. | E31: Pending | G31: Done
A32: PDF_023 | B32: Spreading Screen - Enable Single Click Toggle Visibility | C32: Open the Utilities dropdown, review the Disable Single Click option, and toggle it. | D32: The toggle should be enabled, and the label should switch to Enable Single Click. | E32: Pending | G32: Done
A33: PDF_024 | B33: Spreading Screen - Disable Single Click Mapping Functionality | C33: Open the Utilities dropdown, keep Disable Single Click active, and then map a value from the document to the model. | D33: The user should be able to map the value only by double-clicking. | E33: Pending | G33: Done
A34: PDF_025 | B34: Spreading Screen - Enable Single Click Mapping Functionality | C34: Open the Utilities dropdown, switch the toggle to Enable Single Click, and then map a value from the document to the model. | D34: The user should be able to map the value by single-clicking. | E34: Pending | G34: Done
A35: PDF_026 | B35: Spreading Screen - Merge Mode | C35: In Merge Mode, select two consecutive rows in a table where a line item is split across rows, then right-click and choose Merge Row(s). | D35: The selected rows should be merged. | E35: Pending | G35: Done
A36: PDF_027 | B36: Spreading Screen - Split Rows | C36: After merging rows, select the merged row and choose Split Row(s) from the right-click menu. | D36: The merged row should be split back into separate rows. | E36: Pending | G36: Done
A37: PDF_028 | B37: Spreading Screen - Clear Zone Icon | C37: Clear a zone from the current page by clicking the clear icon next to the zone name under the relevant category. | D37: The selected zone should be removed from the document pane, and any mapping from that zone to the model should also be removed. | E37: Pending | G37: Done
A38: PDF_029 | B38: Spreading Screen - Doc to Model Option Visibility | C38: Open the Navigation category in the document pane. | D38: The Doc to Model option should be displayed under the Navigation category. | E38: Pending | G38: Done
... A46: PDF_037 | B46: Spreading Screen - Split Window Functionality | C46: Use the Split Window option on the Spreading screen to split the financial document into two panes. | D46: The document should be displayed in two panes. | E46: Pending | G46: Done
A47: PDF_038 | B47: Spreading Screen - Split Window Mapping Functionality | C47: Enable Split Window and map values using either pane. | D47: The user should be able to map values from both panes. | E47: Pending | F47: 70985 | G47: Done
A48: PDF_039 | B48: Spreading Screen - Close Split Window Pane | C48: Close the split window pane after opening Split Window. | D48: The extra pane should be closed, and the document should return to a single-pane view. | E48: Pending | G48: Done
...

Sheet Spreading Screen_Excel File
B2: Test Case Summary
B3: Total Test Cases | D3: =SUM(D4:D8) | E3: Executed Tests | F3: Total Tests
B4: Passed | D4: =COUNTIF(F9:F1500,"Passed") | E4: =IF(D4=0,,(D4/(D4+D5))) | F4: =IF(D3=0,,(D4/D3))
B5: Failed | D5: =COUNTIF(F9:F1500,"Failed") | E5: =IF(D5=0,,(D5/(D5+D6))) | F5: =IF(D3=0,,(D5/D3))
B6: Blocked | D6: =COUNTIF(F9:F1500,"Blocked") | E6: =IF(D6=0,,(D6/(D6+D7))) | F6: =IF(D3=0,,(D6/D3))
B7: Pending | D7: =COUNTIF(F9:F1500,"Pending") | E7: =IF(D7=0,,(D7/(D7+D8))) | F7: =IF(D3=0,,(D7/D3))
B8: Not Applicable | D8: =COUNTIF(F9:F150,"Not Applicable") | E8: =IF(D8=0,,(D8/(D8+#REF!))) | F8: =IF(D3=0,,(D8/D3))
B9: S.No. | C9: Module/Sub-Module | D9: Test Steps | E9: Expected Results | F9: Result | G9: Bug ID | H9: Comments
B10: Excl_001 | C10: Spreading screen - Landing Page | D10: 1. Log in and navigate to the Dashboard page. 2. On the Dashboard page, click the Spreading tab and verify that the "Create Customer" text link is visible. 3. Click "Create Customer", enter the required details, and click Create. 4. On the Customer screen, verify that the "Add Item" button is visible and click it. 5. On the Add Item screen, upload the Excel file and enter values in all mandatory fields. 6. Click "Add Item" and proceed to the item details screen. 7. Add the remaining item details and save the item. | E10: The user should be able to create an item for an Excel file. | F10: Pending
B11: Excl_002 | C11: Spreading screen | D11: 1. Log in and navigate to the Dashboard page. 2. On the Dashboard page, click the Spreading tab and verify that the "Create Customer" text link is visible. 3. Click "Create Customer", enter the required details, and click Create. 4. On the Customer screen, verify that the "Add Item" button is visible and click it. 5. On the Add Item screen, upload the Excel file and enter values in all mandatory fields. 6. Click "Add Item" and proceed to the item details screen. 7. Review the "Spread" action for created item and click it and it should navigate to Spreading screen. | E11: The Spreading screen should open. | F11: Pending
